Workbook

Sheet Sheet1
A1: Country | B1: ISO2 | C1: Indicator | D1: Unit | E1: Year | F1: Value | G1: pais_id | H1: indicador_code | I1: indicador_id | J1: Daño total ajustado (MUS) | K1: PIB 2024
A2: Afghanistan, Islamic Rep. of | B2: AF | C2: Climate related disasters frequency, Number of Disasters: Flood | D2: Number of | E2: 1980 | F2: 1 | G2: AF | H2: desastres_inundacion | I2: =VLOOKUP(H2,Hoja3!$J$1:$K$25,2,FALSE) -> 7 | K2: 17233052
A3: Afghanistan, Islamic Rep. of | B3: AF | C3: Climate related disasters frequency, Number of Disasters: TOTAL | D3: Number of | E3: 1980 | F3: 1 | G3: AF | H3: desastres_total | I3: =VLOOKUP(H3,Hoja3!$J$1:$K$25,2,FALSE) -> 10 | K3: 17233052
A4: Afghanistan, Islamic Rep. of | B4: AF | C4: Climate related disasters frequency, Number of People Affected: Flood | D4: Number of | E4: 1980 | F4: 30000 | G4: AF | H4: afectados_inundacion | I4: =VLOOKUP(H4,Hoja3!$J$1:$K$25,2,FALSE) -> 14 | K4: 17233052
A5: Afghanistan, Islamic Rep. of | B5: AF | C5: Climate related disasters frequency, Number of People Affected: TOTAL | D5: Number of | E5: 1980 | F5: 30000 | G5: AF | H5: afectados_total | I5: =VLOOKUP(H5,Hoja3!$J$1:$K$25,2,FALSE) -> 17 | K5: 17233052
A6: Argentina | B6: AR | C6: Climate related disasters frequency, Number of Disasters: Flood | D6: Number of | E6: 1980 | F6: 2 | G6: AR | H6: desastres_inundacion | I6: =VLOOKUP(H6,Hoja3!$J$1:$K$25,2,FALSE) -> 7 | K6: 6.4607528e+08
A7: Argentina | B7: AR | C7: Climate related disasters frequency, Number of Disasters: TOTAL | D7: Number of | E7: 1980 | F7: 2 | G7: AR | H7: desastres_total | I7: =VLOOKUP(H7,Hoja3!$J$1:$K$25,2,FALSE) -> 10 | K7: 6.4607528e+08
A8: Argentina | B8: AR | C8: Climate related disasters frequency, Number of People Affected: Flood | D8: Number of | E8: 1980 | F8: 40000 | G8: AR | H8: afectados_inundacion | I8: =VLOOKUP(H8,Hoja3!$J$1:$K$25,2,FALSE) -> 14 | K8: 6.4607528e+08
A9: Argentina | B9: AR | C9: Climate related disasters frequency, Number of People Affected: TOTAL | D9: Number of | E9: 1980 | F9: 40000 | G9: AR | H9: afectados_total | I9: =VLOOKUP(H9,Hoja3!$J$1:$K$25,2,FALSE) -> 17 | K9: 6.4607528e+08
A10: Austria | B10: AT | C10: Climate related disasters frequency, Number of Disasters: Flood | D10: Number of | E10: 1980 | F10: 1 | G10: AT | H10: desastres_inundacion | I10: =VLOOKUP(H10,Hoja3!$J$1:$K$25,2,FALSE) -> 7 | K10: 5.116852e+08
A11: Austria | B11: AT | C11: Climate related disasters frequency, Number of Disasters: TOTAL | D11: Number of | E11: 1980 | F11: 1 | G11: AT | H11: desastres_total | I11: =VLOOKUP(H11,Hoja3!$J$1:$K$25,2,FALSE) -> 10 | K11: 5.116852e+08
A12: Austria | B12: AT | C12: Climate related disasters frequency, Number of People Affected: Flood | D12: Number of | E12: 1980 | F12: 0 | G12: AT | H12: afectados_inundacion | I12: =VLOOKUP(H12,Hoja3!$J$1:$K$25,2,FALSE) -> 14 | K12: 5.116852e+08
A13: Austria | B13: AT | C13: Climate related disasters frequency, Number of People Affected: TOTAL | D13: Number of | E13: 1980 | F13: 0 | G13: AT | H13: afectados_total | I13: =VLOOKUP(H13,Hoja3!$J$1:$K$25,2,FALSE) -> 17 | K13: 5.116852e+08
A14: Bangladesh | B14: BD | C14: Climate related disasters frequency, Number of Disasters: Flood | D14: Number of | E14: 1980 | F14: 1 | G14: BD | H14: desastres_inundacion | I14: =VLOOKUP(H14,Hoja3!$J$1:$K$25,2,FALSE) -> 7 | J14: 570978 | K14: 4.3741533e+08
A15: Bangladesh | B15: BD | C15: Climate related disasters frequency, Number of Disasters: Storm | D15: Number of | E15: 1980 | F15: 1 | G15: BD | H15: desastres_tormenta | I15: =VLOOKUP(H15,Hoja3!$J$1:$K$25,2,FALSE) -> 9 | K15: 4.3741533e+08
A16: Bangladesh | B16: BD | C16: Climate related disasters frequency, Number of Disasters: TOTAL | D16: Number of | E16: 1980 | F16: 2 | G16: BD | H16: desastres_total | I16: =VLOOKUP(H16,Hoja3!$J$1:$K$25,2,FALSE) -> 10 | K16: 4.3741533e+08
A17: Bangladesh | B17: BD | C17: Climate related disasters frequency, Number of People Affected: Flood | D17: Number of | E17: 1980 | F17: 10000000 | G17: BD | H17: afectados_inundacion | I17: =VLOOKUP(H17,Hoja3!$J$1:$K$25,2,FALSE) -> 14 | K17: 4.3741533e+08
A18: Bangladesh | B18: BD | C18: Climate related disasters frequency, Number of People Affected: Storm | D18: Number of | E18: 1980 | F18: 1050 | G18: BD | H18: afectados_tormenta | I18: =VLOOKUP(H18,Hoja3!$J$1:$K$25,2,FALSE) -> 16 | K18: 4.3741533e+08
A19: Bangladesh | B19: BD | C19: Climate related disasters frequency, Number of People Affected: TOTAL | D19: Number of | E19: 1980 | F19: 10001050 | G19: BD | H19: afectados_total | I19: =VLOOKUP(H19,Hoja3!$J$1:$K$25,2,FALSE) -> 17 | K19: 4.3741533e+08
A20: Barbados | B20: BB | C20: Climate related disasters frequency, Number of Disasters: Storm | D20: Number of | E20: 1980 | F20: 1 | G20: BB | H20: desastres_tormenta | I20: =VLOOKUP(H20,Hoja3!$J$1:$K$25,2,FALSE) -> 9 | J20: 5710 | K20: 6720733.2
A21: Barbados | B21: BB | C21: Climate related disasters frequency, Number of Disasters: TOTAL | D21: Number of | E21: 1980 | F21: 1 | G21: BB | H21: desastres_total | I21: =VLOOKUP(H21,Hoja3!$J$1:$K$25,2,FALSE) -> 10 | K21: 6720733.2
A22: Barbados | B22: BB | C22: Climate related disasters frequency, Number of People Affected: Storm | D22: Number of | E22: 1980 | F22: 5007 | G22: BB | H22: afectados_tormenta | I22: =VLOOKUP(H22,Hoja3!$J$1:$K$25,2,FALSE) -> 16 | K22: 6720733.2
A23: Barbados | B23: BB | C23: Climate related disasters frequency, Number of People Affected: TOTAL | D23: Number of | E23: 1980 | F23: 5007 | G23: BB | H23: afectados_total | I23: =VLOOKUP(H23,Hoja3!$J$1:$K$25,2,FALSE) -> 17 | K23: 6720733.2
A24: Bolivia | B24: BO | C24: Climate related disasters frequency, Number of Disasters: Flood | D24: Number of | E24: 1980 | F24: 1 | G24: BO | H24: desastres_inundacion | I24: =VLOOKUP(H24,Hoja3!$J$1:$K$25,2,FALSE) -> 7 | K24: 45135398
A25: Bolivia | B25: BO | C25: Climate related disasters frequency, Number of Disasters: TOTAL | D25: Number of | E25: 1980 | F25: 1 | G25: BO | H25: desastres_total | I25: =VLOOKUP(H25,Hoja3!$J$1:$K$25,2,FALSE) -> 10 | K25: 45135398
A26: Bolivia | B26: BO | C26: Climate related disasters frequency, Number of People Affected: Flood | D26: Number of | E26: 1980 | F26: 15000 | G26: BO | H26: afectados_inundacion | I26: =VLOOKUP(H26,Hoja3!$J$1:$K$25,2,FALSE) -> 14 | K26: 45135398
A27: Bolivia | B27: BO | C27: Climate related disasters frequency, Number of People Affected: TOTAL | D27: Number of | E27: 1980 | F27: 15000 | G27: BO | H27: afectados_total | I27: =VLOOKUP(H27,Hoja3!$J$1:$K$25,2,FALSE) -> 17 | K27: 45135398
A28: Brazil | B28: BR | C28: Climate related disasters frequency, Number of Disasters: Flood | D28: Number of | E28: 1980 | F28: 2 | G28: BR | H28: desastres_inundacion | I28: =VLOOKUP(H28,Hoja3!$J$1:$K$25,2,FALSE) -> 7 | K28: 2.1736657e+09
A29: Brazil | B29: BR | C29: Climate related disasters frequency, Number of Disasters: Storm | D29: Number of | E29: 1980 | F29: 1 | G29: BR | H29: desastres_tormenta | I29: =VLOOKUP(H29,Hoja3!$J$1:$K$25,2,FALSE) -> 9 | K29: 2.1736657e+09
A30: Brazil | B30: BR | C30: Climate related disasters frequency, Number of Disasters: TOTAL | D30: Number of | E30: 1980 | F30: 3 | G30: BR | H30: desastres_total | I30: =VLOOKUP(H30,Hoja3!$J$1:$K$25,2,FALSE) -> 10 | K30: 2.1736657e+09
A31: Brazil | B31: BR | C31: Climate related disasters frequency, Number of People Affected: Flood | D31: Number of | E31: 1980 | F31: 271000 | G31: BR | H31: afectados_inundacion | I31: =VLOOKUP(H31,Hoja3!$J$1:$K$25,2,FALSE) -> 14 | K31: 2.1736657e+09
A32: Brazil | B32: BR | C32: Climate related disasters frequency, Number of People Affected: Storm | D32: Number of | E32: 1980 | F32: 48 | G32: BR | H32: afectados_tormenta | I32: =VLOOKUP(H32,Hoja3!$J$1:$K$25,2,FALSE) -> 16 | K32: 2.1736657e+09
... A75: Dominica | B75: DM | C75: Climate related disasters frequency, Number of People Affected: TOTAL | D75: Number of | E75: 1980 | F75: 0 | G75: DM | H75: afectados_total | I75: =VLOOKUP(H75,Hoja3!$J$1:$K$25,2,FALSE) -> 17 | K75: 653992.59
A76: Dominican Rep. | B76: DO | C76: Climate related disasters frequency, Number of Disasters: Storm | D76: Number of | E76: 1980 | F76: 1 | G76: DO | H76: desastres_tormenta | I76: =VLOOKUP(H76,Hoja3!$J$1:$K$25,2,FALSE) -> 9 | J76: 178906 | K76: 1.2144428e+08
A77: Dominican Rep. | B77: DO | C77: Climate related disasters frequency, Number of Disasters: TOTAL | D77: Number of | E77: 1980 | F77: 1 | G77: DO | H77: desastres_total | I77: =VLOOKUP(H77,Hoja3!$J$1:$K$25,2,FALSE) -> 10 | K77: 1.2144428e+08
A78: Dominican Rep. | B78: DO | C78: Climate related disasters frequency, Number of People Affected: Storm | D78: Number of | E78: 1980 | F78: 0 | G78: DO | H78: afectados_tormenta | I78: =VLOOKUP(H78,Hoja3!$J$1:$K$25,2,FALSE) -> 16 | K78: 1.2144428e+08
A79: Dominican Rep. | B79: DO | C79: Climate related disasters frequency, Number of People Affected: TOTAL | D79: Number of | E79: 1980 | F79: 0 | G79: DO | H79: afectados_total | I79: =VLOOKUP(H79,Hoja3!$J$1:$K$25,2,FALSE) -> 17 | K79: 1.2144428e+08
A80: Fiji, Rep. of | B80: FJ | C80: Climate related disasters frequency, Number of Disasters: Storm | D80: Number of | E80: 1980 | F80: 1 | G80: FJ | H80: desastres_tormenta | I80: =VLOOKUP(H80,Hoja3!$J$1:$K$25,2,FALSE) -> 9 | J80: 8588 | K80: 5442046.6
A81: Fiji, Rep. of | B81: FJ | C81: Climate related disasters frequency, Number of Disasters: TOTAL | D81: Number of | E81: 1980 | F81: 1 | G81: FJ | H81: desastres_total | I81: =VLOOKUP(H81,Hoja3!$J$1:$K$25,2,FALSE) -> 10 | K81: 5442046.6
A82: Fiji, Rep. of | B82: FJ | C82: Climate related disasters frequency, Number of People Affected: Storm | D82: Number of | E82: 1980 | F82: 35250 | G82: FJ | H82: afectados_tormenta | I82: =VLOOKUP(H82,Hoja3!$J$1:$K$25,2,FALSE) -> 16 | K82: 5442046.6
...

Sheet Hoja1
A1: indicador_code | B1: ingles
A2: desastres_inundacion | B2: Flood
A3: desastres_total | B3: No aplica
A4: afectados_inundacion | B4: No aplica | D4: Flood
A5: afectados_total | B5: No aplica | D5: Storm
A6: desastres_tormenta | B6: Storm | D6: Drought
A7: afectados_tormenta | B7: No aplica | D7: Wildfire
A8: desastres_sequia | B8: Drought | D8: Extreme temperature
A9: afectados_sequia | B9: No aplica | D9: Landslide
A10: desastres_incendios | B10: Wildfire
A11: afectados_incendios | B11: No aplica
A12: desastres_temp_extrema | B12: Extreme temperature
A13: desastres_deslizamiento | B13: Landslide
A14: afectados_temp_extrema | B14: No aplica
A15: afectados_deslizamiento | B15: No aplica

Sheet Hoja2
A1: ISO2 | B1: ISO3
A2: AF | B2: AFG
A3: AF | B3: AFG
A4: AF | B4: AFG
A5: AF | B5: AFG
A6: AF | B6: AFG
A7: AF | B7: AFG
A8: AF | B8: AFG
A9: AF | B9: AFG
A10: AF | B10: AFG
A11: AF | B11: AFG
A12: AF | B12: AFG
... A127: AZ | B127: AZE
B128: AZO
B129: AZO
B130: AZO
B131: AZO
B132: AZO
B133: AZO
A134: BS | B134: BHS
A135: BS | B135: BHS
A136: BS | B136: BHS
A137: BS | B137: BHS
A138: BS | B138: BHS
A139: BS | B139: BHS
A140: BD | B140: BGD
A141: BD | B141: BGD
A142: BD | B142: BGD
A143: BD | B143: BGD
A144: BD | B144: BGD
A145: BD | B145: BGD
... A327: CA | B327: CAN
B328: SPI
B329: SPI
B330: SPI
B331: SPI
B332: SPI
B333: SPI
B334: SPI
B335: SPI
...

Sheet Hoja3
A1: '1' | B1: 'temperaturas' | C1: 'Temperatura media' | D1: '2' | E1: '1' | I1: =SUBSTITUTE(A1,"'","") -> 1 | J1: =TRIM(SUBSTITUTE(B1,"'","")) -> temperaturas | K1: 1
A2: '2' | B2: 'emision_co2' | C2: 'Emisión de CO₂' | D2: '1' | E2: '1' | I2: =SUBSTITUTE(A2,"'","") -> 2 | J2: =TRIM(SUBSTITUTE(B2,"'","")) -> emision_co2 | K2: 2
A3: '3' | B3: 'NY.GDP.MKTP.CD' | C3: 'Producto Interno Bruto (PIB)' | D3: '3' | E3: '2' | I3: =SUBSTITUTE(A3,"'","") -> 3 | J3: =TRIM(SUBSTITUTE(B3,"'","")) -> NY.GDP.MKTP.CD | K3: 3
A4: '4' | B4: 'AG.LND.TOTL.K2' | C4: 'Superficie terrestre total (excluye aguas interiores y ZEE)' | D4: '8' | E4: '3' | I4: =SUBSTITUTE(A4,"'","") -> 4 | J4: =TRIM(SUBSTITUTE(B4,"'","")) -> AG.LND.TOTL.K2 | K4: 4
A5: '5' | B5: 'desastres_sequia' | C5: 'Número de sequías' | D5: '9' | E5: '4' | I5: =SUBSTITUTE(A5,"'","") -> 5 | J5: =TRIM(SUBSTITUTE(B5,"'","")) -> desastres_sequia | K5: 5
A6: '6' | B6: 'desastres_temp_extrema' | C6: 'Número de olas de calor / frío extremo' | D6: '9' | E6: '4' | I6: =SUBSTITUTE(A6,"'","") -> 6 | J6: =TRIM(SUBSTITUTE(B6,"'","")) -> desastres_temp_extrema | K6: 6
A7: '7' | B7: 'desastres_inundacion' | C7: 'Número de inundaciones' | D7: '9' | E7: '4' | I7: =SUBSTITUTE(A7,"'","") -> 7 | J7: =TRIM(SUBSTITUTE(B7,"'","")) -> desastres_inundacion | K7: 7 | L7: desastres_inundacion | N7: =J7=L7 -> TRUE
A8: '8' | B8: 'desastres_deslizamiento' | C8: 'Número de deslizamientos' | D8: '9' | E8: '4' | I8: =SUBSTITUTE(A8,"'","") -> 8 | J8: =TRIM(SUBSTITUTE(B8,"'","")) -> desastres_deslizamiento | K8: 8
A9: '9' | B9: 'desastres_tormenta' | C9: 'Número de tormentas' | D9: '9' | E9: '4' | I9: =SUBSTITUTE(A9,"'","") -> 9 | J9: =TRIM(SUBSTITUTE(B9,"'","")) -> desastres_tormenta | K9: 9
A10: '10' | B10: 'desastres_total' | C10: 'Número total de desastres' | D10: '9' | E10: '4' | I10: =SUBSTITUTE(A10,"'","") -> 10 | J10: =TRIM(SUBSTITUTE(B10,"'","")) -> desastres_total | K10: 10
A11: '11' | B11: 'desastres_incendios' | C11: 'Número de incendios forestales' | D11: '9' | E11: '4' | I11: =SUBSTITUTE(A11,"'","") -> 11 | J11: =TRIM(SUBSTITUTE(B11,"'","")) -> desastres_incendios | K11: 11
A12: '12' | B12: 'afectados_sequia' | C12: 'Personas afectadas por sequías' | D12: '10' | E12: '4' | I12: =SUBSTITUTE(A12,"'","") -> 12 | J12: =TRIM(SUBSTITUTE(B12,"'","")) -> afectados_sequia | K12: 12
A13: '13' | B13: 'afectados_temp_extrema' | C13: 'Personas afectadas por calor / frío extremo' | D13: '10' | E13: '4' | I13: =SUBSTITUTE(A13,"'","") -> 13 | J13: =TRIM(SUBSTITUTE(B13,"'","")) -> afectados_temp_extrema | K13: 13
A14: '14' | B14: 'afectados_inundacion' | C14: 'Personas afectadas por inundaciones' | D14: '10' | E14: '4' | I14: =SUBSTITUTE(A14,"'","") -> 14 | J14: =TRIM(SUBSTITUTE(B14,"'","")) -> afectados_inundacion | K14: 14
A15: '15' | B15: 'afectados_deslizamiento' | C15: 'Personas afectadas por deslizamientos' | D15: '10' | E15: '4' | I15: =SUBSTITUTE(A15,"'","") -> 15 | J15: =TRIM(SUBSTITUTE(B15,"'","")) -> afectados_deslizamiento | K15: 15
A16: '16' | B16: 'afectados_tormenta' | C16: 'Personas afectadas por tormentas' | D16: '10' | E16: '4' | I16: =SUBSTITUTE(A16,"'","") -> 16 | J16: =TRIM(SUBSTITUTE(B16,"'","")) -> afectados_tormenta | K16: 16
A17: '17' | B17: 'afectados_total' | C17: 'Personas afectadas en total' | D17: '10' | E17: '4' | I17: =SUBSTITUTE(A17,"'","") -> 17 | J17: =TRIM(SUBSTITUTE(B17,"'","")) -> afectados_total | K17: 17
A18: '18' | B18: 'afectados_incendios' | C18: 'Personas afectadas por incendios forestales' | D18: '10' | E18: '4' | I18: =SUBSTITUTE(A18,"'","") -> 18 | J18: =TRIM(SUBSTITUTE(B18,"'","")) -> afectados_incendios | K18: 18
A19: '19' | B19: 'costos_sequia' | C19: 'Costos por sequías' | D19: '11' | E19: '4' | I19: =SUBSTITUTE(A19,"'","") -> 19 | J19: =TRIM(SUBSTITUTE(B19,"'","")) -> costos_sequia | K19: 19
... A25: '25' | B25: 'costos_incendios' | C25: 'Costos por incendios forestales' | D25: '11' | E25: '4' | I25: =SUBSTITUTE(A25,"'","") -> 25 | J25: =TRIM(SUBSTITUTE(B25,"'","")) -> costos_incendios | K25: 25
